2020-01-26 14:58:35,606 ERROR: Exception on /api/users/1 [GET] [in /Users/headshot/microblog/venv/lib/python3.7/site-packages/flask/app.py:1891]
Traceback (most recent call last):
  File "/Users/headshot/microblog/venv/lib/python3.7/site-packages/flask/app.py", line 2446, in wsgi_app
    response = self.full_dispatch_request()
  File "/Users/headshot/microblog/venv/lib/python3.7/site-packages/flask/app.py", line 1951, in full_dispatch_request
    rv = self.handle_user_exception(e)
  File "/Users/headshot/microblog/venv/lib/python3.7/site-packages/flask/app.py", line 1820, in handle_user_exception
    reraise(exc_type, exc_value, tb)
  File "/Users/headshot/microblog/venv/lib/python3.7/site-packages/flask/_compat.py", line 39, in reraise
    raise value
  File "/Users/headshot/microblog/venv/lib/python3.7/site-packages/flask/app.py", line 1949, in full_dispatch_request
    rv = self.dispatch_request()
  File "/Users/headshot/microblog/venv/lib/python3.7/site-packages/flask/app.py", line 1935, in dispatch_request
    return self.view_functions[rule.endpoint](**req.view_args)
  File "/Users/headshot/microblog/app/api/users.py", line 8, in get_user
    return jsonify(User.query.get_or_404(id).to_dict())
  File "/Users/headshot/microblog/app/models.py", line 99, in to_dict
    'last_seen':self.last_seen.isoformat() + 'Z',
AttributeError: 'NoneType' object has no attribute 'isoformat'
2020-01-26 14:59:35,451 ERROR: Exception on /api/users/1 [GET] [in /Users/headshot/microblog/venv/lib/python3.7/site-packages/flask/app.py:1891]
Traceback (most recent call last):
  File "/Users/headshot/microblog/venv/lib/python3.7/site-packages/flask/app.py", line 2446, in wsgi_app
    response = self.full_dispatch_request()
  File "/Users/headshot/microblog/venv/lib/python3.7/site-packages/flask/app.py", line 1951, in full_dispatch_request
    rv = self.handle_user_exception(e)
  File "/Users/headshot/microblog/venv/lib/python3.7/site-packages/flask/app.py", line 1820, in handle_user_exception
    reraise(exc_type, exc_value, tb)
  File "/Users/headshot/microblog/venv/lib/python3.7/site-packages/flask/_compat.py", line 39, in reraise
    raise value
  File "/Users/headshot/microblog/venv/lib/python3.7/site-packages/flask/app.py", line 1949, in full_dispatch_request
    rv = self.dispatch_request()
  File "/Users/headshot/microblog/venv/lib/python3.7/site-packages/flask/app.py", line 1935, in dispatch_request
    return self.view_functions[rule.endpoint](**req.view_args)
  File "/Users/headshot/microblog/app/api/users.py", line 8, in get_user
    return jsonify(User.query.get_or_404(id).to_dict())
  File "/Users/headshot/microblog/app/models.py", line 99, in to_dict
    'username':self.username,
AttributeError: 'NoneType' object has no attribute 'isoformat'
2020-01-26 15:04:03,730 INFO: Microblog startup [in /Users/headshot/microblog/app/__init__.py:80]
2020-01-26 15:04:07,646 ERROR: Exception on /api/users/1 [GET] [in /Users/headshot/microblog/venv/lib/python3.7/site-packages/flask/app.py:1891]
Traceback (most recent call last):
  File "/Users/headshot/microblog/venv/lib/python3.7/site-packages/flask/app.py", line 2446, in wsgi_app
    response = self.full_dispatch_request()
  File "/Users/headshot/microblog/venv/lib/python3.7/site-packages/flask/app.py", line 1951, in full_dispatch_request
    rv = self.handle_user_exception(e)
  File "/Users/headshot/microblog/venv/lib/python3.7/site-packages/flask/app.py", line 1820, in handle_user_exception
    reraise(exc_type, exc_value, tb)
  File "/Users/headshot/microblog/venv/lib/python3.7/site-packages/flask/_compat.py", line 39, in reraise
    raise value
  File "/Users/headshot/microblog/venv/lib/python3.7/site-packages/flask/app.py", line 1949, in full_dispatch_request
    rv = self.dispatch_request()
  File "/Users/headshot/microblog/venv/lib/python3.7/site-packages/flask/app.py", line 1935, in dispatch_request
    return self.view_functions[rule.endpoint](**req.view_args)
  File "/Users/headshot/microblog/app/api/users.py", line 8, in get_user
    return jsonify(User.query.get_or_404(id).to_dict())
  File "/Users/headshot/microblog/app/models.py", line 100, in to_dict
    'last_seen': self.last_seen.isoformat() + 'Z',
AttributeError: 'NoneType' object has no attribute 'isoformat'
2020-01-26 15:06:45,103 INFO: Microblog startup [in /Users/headshot/microblog/app/__init__.py:80]
2020-01-26 15:06:49,226 ERROR: Exception on /api/users/1 [GET] [in /Users/headshot/microblog/venv/lib/python3.7/site-packages/flask/app.py:1891]
Traceback (most recent call last):
  File "/Users/headshot/microblog/venv/lib/python3.7/site-packages/flask/app.py", line 2446, in wsgi_app
    response = self.full_dispatch_request()
  File "/Users/headshot/microblog/venv/lib/python3.7/site-packages/flask/app.py", line 1951, in full_dispatch_request
    rv = self.handle_user_exception(e)
  File "/Users/headshot/microblog/venv/lib/python3.7/site-packages/flask/app.py", line 1820, in handle_user_exception
    reraise(exc_type, exc_value, tb)
  File "/Users/headshot/microblog/venv/lib/python3.7/site-packages/flask/_compat.py", line 39, in reraise
    raise value
  File "/Users/headshot/microblog/venv/lib/python3.7/site-packages/flask/app.py", line 1949, in full_dispatch_request
    rv = self.dispatch_request()
  File "/Users/headshot/microblog/venv/lib/python3.7/site-packages/flask/app.py", line 1935, in dispatch_request
    return self.view_functions[rule.endpoint](**req.view_args)
  File "/Users/headshot/microblog/app/api/users.py", line 8, in get_user
    return jsonify(User.query.get_or_404(id).to_dict())
  File "/Users/headshot/microblog/app/models.py", line 104, in to_dict
    'last_seen': self.last_seen.isoformat() + 'Z',
AttributeError: 'NoneType' object has no attribute 'isoformat'
2020-01-26 15:08:12,591 INFO: Microblog startup [in /Users/headshot/microblog/app/__init__.py:80]
2020-01-26 15:23:44,173 INFO: Microblog startup [in /Users/headshot/microblog/app/__init__.py:80]
2020-01-26 15:25:20,404 ERROR: Exception on /api/users [GET] [in /Users/headshot/microblog/venv/lib/python3.7/site-packages/flask/app.py:1891]
Traceback (most recent call last):
  File "/Users/headshot/microblog/venv/lib/python3.7/site-packages/flask/app.py", line 2446, in wsgi_app
    response = self.full_dispatch_request()
  File "/Users/headshot/microblog/venv/lib/python3.7/site-packages/flask/app.py", line 1951, in full_dispatch_request
    rv = self.handle_user_exception(e)
  File "/Users/headshot/microblog/venv/lib/python3.7/site-packages/flask/app.py", line 1820, in handle_user_exception
    reraise(exc_type, exc_value, tb)
  File "/Users/headshot/microblog/venv/lib/python3.7/site-packages/flask/_compat.py", line 39, in reraise
    raise value
  File "/Users/headshot/microblog/venv/lib/python3.7/site-packages/flask/app.py", line 1949, in full_dispatch_request
    rv = self.dispatch_request()
  File "/Users/headshot/microblog/venv/lib/python3.7/site-packages/flask/app.py", line 1935, in dispatch_request
    return self.view_functions[rule.endpoint](**req.view_args)
  File "/Users/headshot/microblog/app/api/users.py", line 16, in get_users
    data = User.to_collection_dict(User.query.all(),page,per_page,'api.get_users')
  File "/Users/headshot/microblog/app/models.py", line 25, in to_collection_dict
    resources = query.paginate(page,per_page,False)
AttributeError: 'list' object has no attribute 'paginate'
2020-01-26 15:36:10,280 INFO: Microblog startup [in /Users/headshot/microblog/app/__init__.py:80]
2020-01-26 15:36:13,214 ERROR: Exception on /api/users [GET] [in /Users/headshot/microblog/venv/lib/python3.7/site-packages/flask/app.py:1891]
Traceback (most recent call last):
  File "/Users/headshot/microblog/venv/lib/python3.7/site-packages/flask/app.py", line 2446, in wsgi_app
    response = self.full_dispatch_request()
  File "/Users/headshot/microblog/venv/lib/python3.7/site-packages/flask/app.py", line 1951, in full_dispatch_request
    rv = self.handle_user_exception(e)
  File "/Users/headshot/microblog/venv/lib/python3.7/site-packages/flask/app.py", line 1820, in handle_user_exception
    reraise(exc_type, exc_value, tb)
  File "/Users/headshot/microblog/venv/lib/python3.7/site-packages/flask/_compat.py", line 39, in reraise
    raise value
  File "/Users/headshot/microblog/venv/lib/python3.7/site-packages/flask/app.py", line 1949, in full_dispatch_request
    rv = self.dispatch_request()
  File "/Users/headshot/microblog/venv/lib/python3.7/site-packages/flask/app.py", line 1935, in dispatch_request
    return self.view_functions[rule.endpoint](**req.view_args)
  File "/Users/headshot/microblog/app/api/users.py", line 17, in get_users
    data = User.to_collection_dict(models.User.query.all(),page,per_page,'api.get_users')
NameError: name 'models' is not defined
2020-01-26 15:36:52,474 INFO: Microblog startup [in /Users/headshot/microblog/app/__init__.py:80]
